[2024-10-15T14:57:59.607+0000] {taskinstance.py:1157} INFO - Dependencies all met for dep_context=non-requeueable deps ti=<TaskInstance: main_v07.create_schema manual__2024-10-15T14:42:48.385504+00:00 [queued]>
[2024-10-15T14:57:59.615+0000] {taskinstance.py:1157} INFO - Dependencies all met for dep_context=requeueable deps ti=<TaskInstance: main_v07.create_schema manual__2024-10-15T14:42:48.385504+00:00 [queued]>
[2024-10-15T14:57:59.615+0000] {taskinstance.py:1359} INFO - Starting attempt 4 of 6
[2024-10-15T14:57:59.627+0000] {taskinstance.py:1380} INFO - Executing <Task(PostgresOperator): create_schema> on 2024-10-15 14:42:48.385504+00:00
[2024-10-15T14:57:59.632+0000] {standard_task_runner.py:57} INFO - Started process 1546 to run task
[2024-10-15T14:57:59.636+0000] {standard_task_runner.py:84} INFO - Running: ['***', 'tasks', 'run', 'main_v07', 'create_schema', 'manual__2024-10-15T14:42:48.385504+00:00', '--job-id', '35', '--raw', '--subdir', 'DAGS_FOLDER/main.py', '--cfg-path', '/tmp/tmpou7lqp_t']
[2024-10-15T14:57:59.638+0000] {standard_task_runner.py:85} INFO - Job 35: Subtask create_schema
[2024-10-15T14:57:59.683+0000] {task_command.py:415} INFO - Running <TaskInstance: main_v07.create_schema manual__2024-10-15T14:42:48.385504+00:00 [running]> on host 86aea83cc069
[2024-10-15T14:57:59.751+0000] {taskinstance.py:1660} INFO - Exporting env vars: AIRFLOW_CTX_DAG_OWNER='***' AIRFLOW_CTX_DAG_ID='main_v07' AIRFLOW_CTX_TASK_ID='create_schema' AIRFLOW_CTX_EXECUTION_DATE='2024-10-15T14:42:48.385504+00:00' AIRFLOW_CTX_TRY_NUMBER='4' AIRFLOW_CTX_DAG_RUN_ID='manual__2024-10-15T14:42:48.385504+00:00'
[2024-10-15T14:57:59.752+0000] {sql.py:274} INFO - Executing: 
    CREATE TABLE IF NOT EXISTS staging_data (
        work_year INT,
        experience_level VARCHAR(50),
        employment_type VARCHAR(50),
        job_title VARCHAR(100),
        salary DECIMAL(10, 2),
        salary_currency VARCHAR(10),
        salary_in_usd DECIMAL(10, 2),
        employee_residence VARCHAR(100),
        remote_ratio INT CHECK (remote_ratio IN (0, 50, 100)),
        company_location VARCHAR(100),
        company_size CHAR(1) CHECK (company_size IN ('S', 'M', 'L')),
        load_time TIMESTAMP WITH TIME ZONE DEFAULT CURRENT_TIMESTAMP
    );
    
[2024-10-15T14:57:59.759+0000] {base.py:73} INFO - Using connection ID 'postgresid' for task execution.
[2024-10-15T14:57:59.768+0000] {base.py:73} INFO - Using connection ID 'postgresid' for task execution.
[2024-10-15T14:57:59.769+0000] {taskinstance.py:1935} ERROR - Task failed with exception
Traceback (most recent call last):
  File "/home/airflow/.local/lib/python3.8/site-packages/airflow/providers/common/sql/operators/sql.py", line 280, in execute
    output = hook.run(
  File "/home/airflow/.local/lib/python3.8/site-packages/airflow/providers/common/sql/hooks/sql.py", line 385, in run
    with closing(self.get_conn()) as conn:
  File "/home/airflow/.local/lib/python3.8/site-packages/airflow/providers/postgres/hooks/postgres.py", line 154, in get_conn
    self.conn = psycopg2.connect(**conn_args)
  File "/home/airflow/.local/lib/python3.8/site-packages/psycopg2/__init__.py", line 122, in connect
    conn = _connect(dsn, connection_factory=connection_factory, **kwasync)
psycopg2.OperationalError: connection to server at "localhost" (::1), port 5423 failed: Connection refused
	Is the server running on that host and accepting TCP/IP connections?
connection to server at "localhost" (127.0.0.1), port 5423 failed: Connection refused
	Is the server running on that host and accepting TCP/IP connections?

[2024-10-15T14:57:59.778+0000] {taskinstance.py:1398} INFO - Marking task as UP_FOR_RETRY. dag_id=main_v07, task_id=create_schema, execution_date=20241015T144248, start_date=20241015T145759, end_date=20241015T145759
[2024-10-15T14:57:59.787+0000] {standard_task_runner.py:104} ERROR - Failed to execute job 35 for task create_schema (connection to server at "localhost" (::1), port 5423 failed: Connection refused
	Is the server running on that host and accepting TCP/IP connections?
connection to server at "localhost" (127.0.0.1), port 5423 failed: Connection refused
	Is the server running on that host and accepting TCP/IP connections?
; 1546)
[2024-10-15T14:57:59.807+0000] {local_task_job_runner.py:228} INFO - Task exited with return code 1
[2024-10-15T14:57:59.850+0000] {taskinstance.py:2776} INFO - 0 downstream tasks scheduled from follow-on schedule check
