[2024-10-15T17:31:01.420+0000] {local_task_job_runner.py:123} INFO - ::group::Pre task execution logs
[2024-10-15T17:31:01.450+0000] {taskinstance.py:2612} INFO - Dependencies all met for dep_context=non-requeueable deps ti=<TaskInstance: main_v09.create_fact_table manual__2024-10-15T17:31:01.102022+00:00 [queued]>
[2024-10-15T17:31:01.464+0000] {taskinstance.py:2612} INFO - Dependencies all met for dep_context=requeueable deps ti=<TaskInstance: main_v09.create_fact_table manual__2024-10-15T17:31:01.102022+00:00 [queued]>
[2024-10-15T17:31:01.464+0000] {taskinstance.py:2865} INFO - Starting attempt 1 of 6
[2024-10-15T17:31:01.688+0000] {taskinstance.py:2888} INFO - Executing <Task(MySqlOperator): create_fact_table> on 2024-10-15 17:31:01.102022+00:00
[2024-10-15T17:31:01.697+0000] {standard_task_runner.py:72} INFO - Started process 1154 to run task
[2024-10-15T17:31:01.701+0000] {standard_task_runner.py:104} INFO - Running: ['***', 'tasks', 'run', 'main_v09', 'create_fact_table', 'manual__2024-10-15T17:31:01.102022+00:00', '--job-id', '80', '--raw', '--subdir', 'DAGS_FOLDER/main.py', '--cfg-path', '/tmp/tmpfcw9hutm']
[2024-10-15T17:31:01.704+0000] {standard_task_runner.py:105} INFO - Job 80: Subtask create_fact_table
[2024-10-15T17:31:01.772+0000] {task_command.py:467} INFO - Running <TaskInstance: main_v09.create_fact_table manual__2024-10-15T17:31:01.102022+00:00 [running]> on host bdd8237acab7
[2024-10-15T17:31:01.863+0000] {taskinstance.py:3131} INFO - Exporting env vars: AIRFLOW_CTX_DAG_OWNER='***' AIRFLOW_CTX_DAG_ID='main_v09' AIRFLOW_CTX_TASK_ID='create_fact_table' AIRFLOW_CTX_EXECUTION_DATE='2024-10-15T17:31:01.102022+00:00' AIRFLOW_CTX_TRY_NUMBER='1' AIRFLOW_CTX_DAG_RUN_ID='manual__2024-10-15T17:31:01.102022+00:00'
[2024-10-15T17:31:01.864+0000] {taskinstance.py:731} INFO - ::endgroup::
[2024-10-15T17:31:01.881+0000] {sql.py:274} INFO - Executing: 
    USE main;
    
    CREATE TABLE IF NOT EXISTS jobs_fact (
        fact_id INT AUTO_INCREMENT PRIMARY KEY,
        job_id INT,
        employee_id INT,
        company_id INT,
        currency_id INT,
        salary DECIMAL(15, 2) NOT NULL,
        salary_in_usd DECIMAL(15, 2) NOT NULL
    );
    
[2024-10-15T17:31:01.891+0000] {base.py:84} INFO - Retrieving connection 'mariadb'
[2024-10-15T17:31:01.903+0000] {base.py:84} INFO - Retrieving connection 'mariadb'
[2024-10-15T17:31:01.954+0000] {taskinstance.py:3310} ERROR - Task failed with exception
Traceback (most recent call last):
  File "/home/airflow/.local/lib/python3.8/site-packages/airflow/models/taskinstance.py", line 767, in _execute_task
    result = _execute_callable(context=context, **execute_callable_kwargs)
  File "/home/airflow/.local/lib/python3.8/site-packages/airflow/models/taskinstance.py", line 733, in _execute_callable
    return ExecutionCallableRunner(
  File "/home/airflow/.local/lib/python3.8/site-packages/airflow/utils/operator_helpers.py", line 252, in run
    return self.func(*args, **kwargs)
  File "/home/airflow/.local/lib/python3.8/site-packages/airflow/models/baseoperator.py", line 406, in wrapper
    return func(self, *args, **kwargs)
  File "/home/airflow/.local/lib/python3.8/site-packages/airflow/providers/common/sql/operators/sql.py", line 280, in execute
    output = hook.run(
  File "/home/airflow/.local/lib/python3.8/site-packages/airflow/providers/common/sql/hooks/sql.py", line 385, in run
    with closing(self.get_conn()) as conn:
  File "/home/airflow/.local/lib/python3.8/site-packages/airflow/providers/mysql/hooks/mysql.py", line 194, in get_conn
    return MySQLdb.connect(**conn_config)
  File "/home/airflow/.local/lib/python3.8/site-packages/MySQLdb/__init__.py", line 121, in Connect
    return Connection(*args, **kwargs)
  File "/home/airflow/.local/lib/python3.8/site-packages/MySQLdb/connections.py", line 193, in __init__
    super().__init__(*args, **kwargs2)
MySQLdb.OperationalError: (1045, "Access denied for user 'root'@'172.18.0.5' (using password: YES)")
[2024-10-15T17:31:01.975+0000] {taskinstance.py:1225} INFO - Marking task as UP_FOR_RETRY. dag_id=main_v09, task_id=create_fact_table, run_id=manual__2024-10-15T17:31:01.102022+00:00, execution_date=20241015T173101, start_date=20241015T173101, end_date=20241015T173101
[2024-10-15T17:31:01.997+0000] {taskinstance.py:340} INFO - ::group::Post task execution logs
[2024-10-15T17:31:01.997+0000] {standard_task_runner.py:124} ERROR - Failed to execute job 80 for task create_fact_table ((1045, "Access denied for user 'root'@'172.18.0.5' (using password: YES)"); 1154)
Traceback (most recent call last):
  File "/home/airflow/.local/lib/python3.8/site-packages/airflow/task/task_runner/standard_task_runner.py", line 117, in _start_by_fork
    ret = args.func(args, dag=self.dag)
  File "/home/airflow/.local/lib/python3.8/site-packages/airflow/cli/cli_config.py", line 49, in command
    return func(*args, **kwargs)
  File "/home/airflow/.local/lib/python3.8/site-packages/airflow/utils/cli.py", line 115, in wrapper
    return f(*args, **kwargs)
  File "/home/airflow/.local/lib/python3.8/site-packages/airflow/cli/commands/task_command.py", line 483, in task_run
    task_return_code = _run_task_by_selected_method(args, _dag, ti)
  File "/home/airflow/.local/lib/python3.8/site-packages/airflow/cli/commands/task_command.py", line 256, in _run_task_by_selected_method
    return _run_raw_task(args, ti)
  File "/home/airflow/.local/lib/python3.8/site-packages/airflow/cli/commands/task_command.py", line 341, in _run_raw_task
    return ti._run_raw_task(
  File "/home/airflow/.local/lib/python3.8/site-packages/airflow/utils/session.py", line 97, in wrapper
    return func(*args, session=session, **kwargs)
  File "/home/airflow/.local/lib/python3.8/site-packages/airflow/models/taskinstance.py", line 3004, in _run_raw_task
    return _run_raw_task(
  File "/home/airflow/.local/lib/python3.8/site-packages/airflow/models/taskinstance.py", line 273, in _run_raw_task
    TaskInstance._execute_task_with_callbacks(
  File "/home/airflow/.local/lib/python3.8/site-packages/airflow/models/taskinstance.py", line 3158, in _execute_task_with_callbacks
    result = self._execute_task(context, task_orig)
  File "/home/airflow/.local/lib/python3.8/site-packages/airflow/models/taskinstance.py", line 3182, in _execute_task
    return _execute_task(self, context, task_orig)
  File "/home/airflow/.local/lib/python3.8/site-packages/airflow/models/taskinstance.py", line 767, in _execute_task
    result = _execute_callable(context=context, **execute_callable_kwargs)
  File "/home/airflow/.local/lib/python3.8/site-packages/airflow/models/taskinstance.py", line 733, in _execute_callable
    return ExecutionCallableRunner(
  File "/home/airflow/.local/lib/python3.8/site-packages/airflow/utils/operator_helpers.py", line 252, in run
    return self.func(*args, **kwargs)
  File "/home/airflow/.local/lib/python3.8/site-packages/airflow/models/baseoperator.py", line 406, in wrapper
    return func(self, *args, **kwargs)
  File "/home/airflow/.local/lib/python3.8/site-packages/airflow/providers/common/sql/operators/sql.py", line 280, in execute
    output = hook.run(
  File "/home/airflow/.local/lib/python3.8/site-packages/airflow/providers/common/sql/hooks/sql.py", line 385, in run
    with closing(self.get_conn()) as conn:
  File "/home/airflow/.local/lib/python3.8/site-packages/airflow/providers/mysql/hooks/mysql.py", line 194, in get_conn
    return MySQLdb.connect(**conn_config)
  File "/home/airflow/.local/lib/python3.8/site-packages/MySQLdb/__init__.py", line 121, in Connect
    return Connection(*args, **kwargs)
  File "/home/airflow/.local/lib/python3.8/site-packages/MySQLdb/connections.py", line 193, in __init__
    super().__init__(*args, **kwargs2)
MySQLdb.OperationalError: (1045, "Access denied for user 'root'@'172.18.0.5' (using password: YES)")
[2024-10-15T17:31:02.035+0000] {local_task_job_runner.py:266} INFO - Task exited with return code 1
[2024-10-15T17:31:02.045+0000] {local_task_job_runner.py:245} INFO - ::endgroup::
