[2024-10-15T14:53:29.145+0000] {taskinstance.py:1157} INFO - Dependencies all met for dep_context=non-requeueable deps ti=<TaskInstance: main_v07.create_schema manual__2024-10-15T14:43:26.786370+00:00 [queued]>
[2024-10-15T14:53:29.156+0000] {taskinstance.py:1157} INFO - Dependencies all met for dep_context=requeueable deps ti=<TaskInstance: main_v07.create_schema manual__2024-10-15T14:43:26.786370+00:00 [queued]>
[2024-10-15T14:53:29.156+0000] {taskinstance.py:1359} INFO - Starting attempt 3 of 6
[2024-10-15T14:53:29.166+0000] {taskinstance.py:1380} INFO - Executing <Task(PostgresOperator): create_schema> on 2024-10-15 14:43:26.786370+00:00
[2024-10-15T14:53:29.172+0000] {standard_task_runner.py:57} INFO - Started process 1436 to run task
[2024-10-15T14:53:29.178+0000] {standard_task_runner.py:84} INFO - Running: ['***', 'tasks', 'run', 'main_v07', 'create_schema', 'manual__2024-10-15T14:43:26.786370+00:00', '--job-id', '34', '--raw', '--subdir', 'DAGS_FOLDER/main.py', '--cfg-path', '/tmp/tmpytys4t30']
[2024-10-15T14:53:29.182+0000] {standard_task_runner.py:85} INFO - Job 34: Subtask create_schema
[2024-10-15T14:53:29.228+0000] {task_command.py:415} INFO - Running <TaskInstance: main_v07.create_schema manual__2024-10-15T14:43:26.786370+00:00 [running]> on host 86aea83cc069
[2024-10-15T14:53:29.288+0000] {taskinstance.py:1660} INFO - Exporting env vars: AIRFLOW_CTX_DAG_OWNER='***' AIRFLOW_CTX_DAG_ID='main_v07' AIRFLOW_CTX_TASK_ID='create_schema' AIRFLOW_CTX_EXECUTION_DATE='2024-10-15T14:43:26.786370+00:00' AIRFLOW_CTX_TRY_NUMBER='3' AIRFLOW_CTX_DAG_RUN_ID='manual__2024-10-15T14:43:26.786370+00:00'
[2024-10-15T14:53:29.289+0000] {sql.py:274} INFO - Executing: 
    CREATE TABLE IF NOT EXISTS staging_data (
        work_year INT,
        experience_level VARCHAR(50),
        employment_type VARCHAR(50),
        job_title VARCHAR(100),
        salary DECIMAL(10, 2),
        salary_currency VARCHAR(10),
        salary_in_usd DECIMAL(10, 2),
        employee_residence VARCHAR(100),
        remote_ratio INT CHECK (remote_ratio IN (0, 50, 100)),
        company_location VARCHAR(100),
        company_size CHAR(1) CHECK (company_size IN ('S', 'M', 'L')),
        load_time TIMESTAMP WITH TIME ZONE DEFAULT CURRENT_TIMESTAMP
    );
    
[2024-10-15T14:53:29.297+0000] {base.py:73} INFO - Using connection ID 'postgresid' for task execution.
[2024-10-15T14:53:29.306+0000] {base.py:73} INFO - Using connection ID 'postgresid' for task execution.
[2024-10-15T14:53:29.307+0000] {taskinstance.py:1935} ERROR - Task failed with exception
Traceback (most recent call last):
  File "/home/airflow/.local/lib/python3.8/site-packages/airflow/providers/common/sql/operators/sql.py", line 280, in execute
    output = hook.run(
  File "/home/airflow/.local/lib/python3.8/site-packages/airflow/providers/common/sql/hooks/sql.py", line 385, in run
    with closing(self.get_conn()) as conn:
  File "/home/airflow/.local/lib/python3.8/site-packages/airflow/providers/postgres/hooks/postgres.py", line 154, in get_conn
    self.conn = psycopg2.connect(**conn_args)
  File "/home/airflow/.local/lib/python3.8/site-packages/psycopg2/__init__.py", line 122, in connect
    conn = _connect(dsn, connection_factory=connection_factory, **kwasync)
psycopg2.OperationalError: connection to server at "localhost" (::1), port 5423 failed: Connection refused
	Is the server running on that host and accepting TCP/IP connections?
connection to server at "localhost" (127.0.0.1), port 5423 failed: Connection refused
	Is the server running on that host and accepting TCP/IP connections?

[2024-10-15T14:53:29.315+0000] {taskinstance.py:1398} INFO - Marking task as UP_FOR_RETRY. dag_id=main_v07, task_id=create_schema, execution_date=20241015T144326, start_date=20241015T145329, end_date=20241015T145329
[2024-10-15T14:53:29.325+0000] {standard_task_runner.py:104} ERROR - Failed to execute job 34 for task create_schema (connection to server at "localhost" (::1), port 5423 failed: Connection refused
	Is the server running on that host and accepting TCP/IP connections?
connection to server at "localhost" (127.0.0.1), port 5423 failed: Connection refused
	Is the server running on that host and accepting TCP/IP connections?
; 1436)
[2024-10-15T14:53:29.347+0000] {local_task_job_runner.py:228} INFO - Task exited with return code 1
[2024-10-15T14:53:29.390+0000] {taskinstance.py:2776} INFO - 0 downstream tasks scheduled from follow-on schedule check
