[2024-10-16T19:48:07.868+0000] {local_task_job_runner.py:123} INFO - ::group::Pre task execution logs
[2024-10-16T19:48:07.884+0000] {taskinstance.py:2612} INFO - Dependencies all met for dep_context=non-requeueable deps ti=<TaskInstance: main_v10.load_fact_table manual__2024-10-16T19:47:19.764937+00:00 [queued]>
[2024-10-16T19:48:07.893+0000] {taskinstance.py:2612} INFO - Dependencies all met for dep_context=requeueable deps ti=<TaskInstance: main_v10.load_fact_table manual__2024-10-16T19:47:19.764937+00:00 [queued]>
[2024-10-16T19:48:07.894+0000] {taskinstance.py:2865} INFO - Starting attempt 1 of 6
[2024-10-16T19:48:08.024+0000] {taskinstance.py:2888} INFO - Executing <Task(MySqlOperator): load_fact_table> on 2024-10-16 19:47:19.764937+00:00
[2024-10-16T19:48:08.032+0000] {standard_task_runner.py:72} INFO - Started process 3060 to run task
[2024-10-16T19:48:08.037+0000] {standard_task_runner.py:104} INFO - Running: ['***', 'tasks', 'run', 'main_v10', 'load_fact_table', 'manual__2024-10-16T19:47:19.764937+00:00', '--job-id', '104', '--raw', '--subdir', 'DAGS_FOLDER/main.py', '--cfg-path', '/tmp/tmpjvwsmwuz']
[2024-10-16T19:48:08.041+0000] {standard_task_runner.py:105} INFO - Job 104: Subtask load_fact_table
[2024-10-16T19:48:08.084+0000] {task_command.py:467} INFO - Running <TaskInstance: main_v10.load_fact_table manual__2024-10-16T19:47:19.764937+00:00 [running]> on host ff82e7275d8f
[2024-10-16T19:48:08.157+0000] {taskinstance.py:3131} INFO - Exporting env vars: AIRFLOW_CTX_DAG_OWNER='***' AIRFLOW_CTX_DAG_ID='main_v10' AIRFLOW_CTX_TASK_ID='load_fact_table' AIRFLOW_CTX_EXECUTION_DATE='2024-10-16T19:47:19.764937+00:00' AIRFLOW_CTX_TRY_NUMBER='1' AIRFLOW_CTX_DAG_RUN_ID='manual__2024-10-16T19:47:19.764937+00:00'
[2024-10-16T19:48:08.157+0000] {taskinstance.py:731} INFO - ::endgroup::
[2024-10-16T19:48:08.168+0000] {sql.py:274} INFO - Executing: 
    CREATE PROCEDURE load_fact()
    BEGIN
        INSERT INTO jobs_fact (
            job_id,
            employee_id,
            company_id,
            currency_id,
            salary,
            salary_in_usd
        )
        SELECT 
            j.job_id,
            e.employee_id,
            c.company_id,
            cu.currency_id,
            b.salary,
            b.salary_in_usd
        FROM big_table b
        JOIN job_dim j ON j.job_id = b.id
        JOIN employee_dim e ON e.employee_id = b.id
        JOIN company_dim c ON c.company_id = b.id
        JOIN currency_dim cu ON cu.currency_id = b.id;
    END;

    CALL load_fact();
    
[2024-10-16T19:48:08.178+0000] {base.py:84} INFO - Retrieving connection 'mariadb'
[2024-10-16T19:48:08.186+0000] {base.py:84} INFO - Retrieving connection 'mariadb'
[2024-10-16T19:48:08.205+0000] {sql.py:418} INFO - Running statement: 
    CREATE PROCEDURE load_fact()
    BEGIN
        INSERT INTO jobs_fact (
            job_id,
            employee_id,
            company_id,
            currency_id,
            salary,
            salary_in_usd
        )
        SELECT 
            j.job_id,
            e.employee_id,
            c.company_id,
            cu.currency_id,
            b.salary,
            b.salary_in_usd
        FROM big_table b
        JOIN job_dim j ON j.job_id = b.id
        JOIN employee_dim e ON e.employee_id = b.id
        JOIN company_dim c ON c.company_id = b.id
        JOIN currency_dim cu ON cu.currency_id = b.id;
    END;

    CALL load_fact();
    , parameters: None
[2024-10-16T19:48:08.206+0000] {taskinstance.py:3310} ERROR - Task failed with exception
Traceback (most recent call last):
  File "/home/airflow/.local/lib/python3.8/site-packages/airflow/models/taskinstance.py", line 767, in _execute_task
    result = _execute_callable(context=context, **execute_callable_kwargs)
  File "/home/airflow/.local/lib/python3.8/site-packages/airflow/models/taskinstance.py", line 733, in _execute_callable
    return ExecutionCallableRunner(
  File "/home/airflow/.local/lib/python3.8/site-packages/airflow/utils/operator_helpers.py", line 252, in run
    return self.func(*args, **kwargs)
  File "/home/airflow/.local/lib/python3.8/site-packages/airflow/models/baseoperator.py", line 406, in wrapper
    return func(self, *args, **kwargs)
  File "/home/airflow/.local/lib/python3.8/site-packages/airflow/providers/common/sql/operators/sql.py", line 280, in execute
    output = hook.run(
  File "/home/airflow/.local/lib/python3.8/site-packages/airflow/providers/common/sql/hooks/sql.py", line 392, in run
    self._run_command(cur, sql_statement, parameters)
  File "/home/airflow/.local/lib/python3.8/site-packages/airflow/providers/common/sql/hooks/sql.py", line 423, in _run_command
    cur.execute(sql_statement)
  File "/home/airflow/.local/lib/python3.8/site-packages/MySQLdb/cursors.py", line 179, in execute
    res = self._query(mogrified_query)
  File "/home/airflow/.local/lib/python3.8/site-packages/MySQLdb/cursors.py", line 330, in _query
    db.query(q)
  File "/home/airflow/.local/lib/python3.8/site-packages/MySQLdb/connections.py", line 255, in query
    _mysql.connection.query(self, query)
MySQLdb.OperationalError: (1304, 'PROCEDURE load_fact already exists')
[2024-10-16T19:48:08.219+0000] {taskinstance.py:1225} INFO - Marking task as UP_FOR_RETRY. dag_id=main_v10, task_id=load_fact_table, run_id=manual__2024-10-16T19:47:19.764937+00:00, execution_date=20241016T194719, start_date=20241016T194807, end_date=20241016T194808
[2024-10-16T19:48:08.235+0000] {taskinstance.py:340} INFO - ::group::Post task execution logs
[2024-10-16T19:48:08.235+0000] {standard_task_runner.py:124} ERROR - Failed to execute job 104 for task load_fact_table ((1304, 'PROCEDURE load_fact already exists'); 3060)
Traceback (most recent call last):
  File "/home/airflow/.local/lib/python3.8/site-packages/airflow/task/task_runner/standard_task_runner.py", line 117, in _start_by_fork
    ret = args.func(args, dag=self.dag)
  File "/home/airflow/.local/lib/python3.8/site-packages/airflow/cli/cli_config.py", line 49, in command
    return func(*args, **kwargs)
  File "/home/airflow/.local/lib/python3.8/site-packages/airflow/utils/cli.py", line 115, in wrapper
    return f(*args, **kwargs)
  File "/home/airflow/.local/lib/python3.8/site-packages/airflow/cli/commands/task_command.py", line 483, in task_run
    task_return_code = _run_task_by_selected_method(args, _dag, ti)
  File "/home/airflow/.local/lib/python3.8/site-packages/airflow/cli/commands/task_command.py", line 256, in _run_task_by_selected_method
    return _run_raw_task(args, ti)
  File "/home/airflow/.local/lib/python3.8/site-packages/airflow/cli/commands/task_command.py", line 341, in _run_raw_task
    return ti._run_raw_task(
  File "/home/airflow/.local/lib/python3.8/site-packages/airflow/utils/session.py", line 97, in wrapper
    return func(*args, session=session, **kwargs)
  File "/home/airflow/.local/lib/python3.8/site-packages/airflow/models/taskinstance.py", line 3004, in _run_raw_task
    return _run_raw_task(
  File "/home/airflow/.local/lib/python3.8/site-packages/airflow/models/taskinstance.py", line 273, in _run_raw_task
    TaskInstance._execute_task_with_callbacks(
  File "/home/airflow/.local/lib/python3.8/site-packages/airflow/models/taskinstance.py", line 3158, in _execute_task_with_callbacks
    result = self._execute_task(context, task_orig)
  File "/home/airflow/.local/lib/python3.8/site-packages/airflow/models/taskinstance.py", line 3182, in _execute_task
    return _execute_task(self, context, task_orig)
  File "/home/airflow/.local/lib/python3.8/site-packages/airflow/models/taskinstance.py", line 767, in _execute_task
    result = _execute_callable(context=context, **execute_callable_kwargs)
  File "/home/airflow/.local/lib/python3.8/site-packages/airflow/models/taskinstance.py", line 733, in _execute_callable
    return ExecutionCallableRunner(
  File "/home/airflow/.local/lib/python3.8/site-packages/airflow/utils/operator_helpers.py", line 252, in run
    return self.func(*args, **kwargs)
  File "/home/airflow/.local/lib/python3.8/site-packages/airflow/models/baseoperator.py", line 406, in wrapper
    return func(self, *args, **kwargs)
  File "/home/airflow/.local/lib/python3.8/site-packages/airflow/providers/common/sql/operators/sql.py", line 280, in execute
    output = hook.run(
  File "/home/airflow/.local/lib/python3.8/site-packages/airflow/providers/common/sql/hooks/sql.py", line 392, in run
    self._run_command(cur, sql_statement, parameters)
  File "/home/airflow/.local/lib/python3.8/site-packages/airflow/providers/common/sql/hooks/sql.py", line 423, in _run_command
    cur.execute(sql_statement)
  File "/home/airflow/.local/lib/python3.8/site-packages/MySQLdb/cursors.py", line 179, in execute
    res = self._query(mogrified_query)
  File "/home/airflow/.local/lib/python3.8/site-packages/MySQLdb/cursors.py", line 330, in _query
    db.query(q)
  File "/home/airflow/.local/lib/python3.8/site-packages/MySQLdb/connections.py", line 255, in query
    _mysql.connection.query(self, query)
MySQLdb.OperationalError: (1304, 'PROCEDURE load_fact already exists')
[2024-10-16T19:48:08.247+0000] {local_task_job_runner.py:266} INFO - Task exited with return code 1
[2024-10-16T19:48:08.289+0000] {taskinstance.py:3900} INFO - 0 downstream tasks scheduled from follow-on schedule check
[2024-10-16T19:48:08.291+0000] {local_task_job_runner.py:245} INFO - ::endgroup::
